fn main() -> Result<(), failure::Error> {
    Ok(())
}
